<?xml version="1.0" encoding="UTF-8"?>
<testng-results skipped="0" failed="1" ignored="0" total="3" passed="2">
  <reporter-output>
  </reporter-output>
  <suite name="Test" duration-ms="46" started-at="2020-06-22T09:49:21Z" finished-at="2020-06-22T09:49:21Z">
    <groups>
    </groups>
    <test name="Test01_test01" duration-ms="46" started-at="2020-06-22T09:49:21Z" finished-at="2020-06-22T09:49:21Z">
      <class name="com.course.Test01">
        <test-method status="FAIL" signature="test01()[pri:0, instance:com.course.Test01@4f47d241]" name="test01" duration-ms="10" started-at="2020-06-22T17:49:21Z" finished-at="2020-06-22T17:49:21Z">
          <exception class="java.lang.AssertionError">
            <message>
              <![CDATA[expected [2] but found [1]]]>
            </message>
            <full-stacktrace>
              <![CDATA[java.lang.AssertionError: expected [2] but found [1]
	at org.testng.Assert.fail(Assert.java:94)
	at org.testng.Assert.failNotEquals(Assert.java:513)
	at org.testng.Assert.assertEqualsImpl(Assert.java:135)
	at org.testng.Assert.assertEquals(Assert.java:116)
	at org.testng.Assert.assertEquals(Assert.java:389)
	at org.testng.Assert.assertEquals(Assert.java:399)
	at com.course.Test01.test01(Test01.java:11)
	at sun.reflect.NativeMethodAccessorImpl.invoke0(Native Method)
	at sun.reflect.NativeMethodAccessorImpl.invoke(Unknown Source)
	at sun.reflect.DelegatingMethodAccessorImpl.invoke(Unknown Source)
	at java.lang.reflect.Method.invoke(Unknown Source)
	at org.testng.internal.MethodInvocationHelper.invokeMethod(MethodInvocationHelper.java:104)
	at org.testng.internal.Invoker.invokeMethod(Invoker.java:645)
	at org.testng.internal.Invoker.invokeTestMethod(Invoker.java:851)
	at org.testng.internal.Invoker.invokeTestMethods(Invoker.java:1177)
	at org.testng.internal.TestMethodWorker.invokeTestMethods(TestMethodWorker.java:129)
	at org.testng.internal.TestMethodWorker.run(TestMethodWorker.java:112)
	at org.testng.TestRunner.privateRun(TestRunner.java:756)
	at org.testng.TestRunner.run(TestRunner.java:610)
	at org.testng.SuiteRunner.runTest(SuiteRunner.java:387)
	at org.testng.SuiteRunner.runSequentially(SuiteRunner.java:382)
	at org.testng.SuiteRunner.privateRun(SuiteRunner.java:340)
	at org.testng.SuiteRunner.run(SuiteRunner.java:289)
	at org.testng.SuiteRunnerWorker.runSuite(SuiteRunnerWorker.java:52)
	at org.testng.SuiteRunnerWorker.run(SuiteRunnerWorker.java:86)
	at org.testng.TestNG.runSuitesSequentially(TestNG.java:1293)
	at org.testng.TestNG.runSuitesLocally(TestNG.java:1218)
	at org.testng.TestNG.runSuites(TestNG.java:1133)
	at org.testng.TestNG.run(TestNG.java:1104)
	at com.course.Test03.main(Test03.java:22)
]]>
            </full-stacktrace>
          </exception> <!-- java.lang.AssertionError -->
          <reporter-output>
          </reporter-output>
        </test-method> <!-- test01 -->
        <test-method status="PASS" signature="test02()[pri:0, instance:com.course.Test01@4f47d241]" name="test02" duration-ms="0" started-at="2020-06-22T17:49:21Z" finished-at="2020-06-22T17:49:21Z">
          <reporter-output>
          </reporter-output>
        </test-method> <!-- test02 -->
        <test-method status="PASS" signature="test03()[pri:0, instance:com.course.Test01@4f47d241]" name="test03" duration-ms="0" started-at="2020-06-22T17:49:21Z" finished-at="2020-06-22T17:49:21Z">
          <reporter-output>
          </reporter-output>
        </test-method> <!-- test03 -->
      </class> <!-- com.course.Test01 -->
    </test> <!-- Test01_test01 -->
  </suite> <!-- Test -->
</testng-results>
